<?xml version="1.0"?>
<robot xmlns:xacro="http://ros.org/wiki/xacro">
  <xacro:macro name="abb_irb4600_60_205" params="prefix">
    <!-- link list -->
    <link name="${prefix}base_link">
      <inertial>
        <mass value="13.7742"/>
        <origin xyz="-0.028986 0.000596 0.11273"/>
        <inertia ixx="0.101998" ixy="0.000495482" ixz="0.000311158" iyy="0.13969" iyz="-0.000245375" izz="0.130433"/>
      </inertial>
      <collision name="collision">
        <geometry>
          <mesh filename="package://abb_irb4600_gazebo/meshes/irb4600_60_205/collision/base_link.stl"/>
        </geometry>
      </collision>
      <visual name="visual">
        <geometry>
          <mesh filename="package://abb_irb4600_gazebo/meshes/irb4600_60_205/visual/base_link.stl"/>
        </geometry>
        <material name="yellow">
          <color rgba="1 1 0 1"/>
        </material>
      </visual>
    </link>
    <link name="${prefix}link_1">
      <inertial>
        <mass value="11.8419"/>
        <origin xyz="0.000877 -0.000631 -0.062883"/>
        <inertia ixx="0.11194" ixy="-4.54988e-05" ixz="0.000280961" iyy="0.0915159" iyz="-0.000109905" izz="0.0876456"/>
      </inertial>
      <collision name="collision">
        <geometry>
          <mesh filename="package://abb_irb4600_gazebo/meshes/irb4600_60_205/collision/link_1.stl"/>
        </geometry>
      </collision>
      <visual name="visual">
        <geometry>
          <mesh filename="package://abb_irb4600_gazebo/meshes/irb4600_60_205/visual/link_1.stl"/>
        </geometry>
        <material name="yellow"/>
      </visual>
    </link>
    <link name="${prefix}link_2">
      <inertial>
        <mass value="17.5394"/>
        <origin xyz="-0.000928 -0.000497 0.250051"/>
        <inertia ixx="0.493558" ixy="1.32136e-05" ixz="0.000209024" iyy="0.462939" iyz="-0.00179901" izz="0.0894214"/>
      </inertial>
      <collision name="collision">
        <geometry>
          <mesh filename="package://abb_irb4600_gazebo/meshes/irb4600_60_205/collision/link_2.stl"/>
        </geometry>
      </collision>
      <visual name="visual">
        <geometry>
          <mesh filename="package://abb_irb4600_gazebo/meshes/irb4600_60_205/visual/link_2.stl"/>
        </geometry>
        <material name="yellow"/>
      </visual>
    </link>
    <link name="${prefix}link_3">
      <inertial>
        <mass value="7.46365"/>
        <origin xyz="0.099588 0.001143 0.032333"/>
        <inertia ixx="0.0252424" ixy="0.000142737" ixz="-0.00565542" iyy="0.0906438" iyz="0.000142213" izz="0.0825079"/>
      </inertial>
      <collision name="collision">
        <geometry>
          <mesh filename="package://abb_irb4600_gazebo/meshes/irb4600_60_205/collision/link_3.stl"/>
        </geometry>
      </collision>
      <visual name="visual">
        <geometry>
          <mesh filename="package://abb_irb4600_gazebo/meshes/irb4600_60_205/visual/link_3.stl"/>
        </geometry>
        <material name="yellow"/>
      </visual>
    </link>
    <link name="${prefix}link_4">
      <inertial>
        <mass value="2.74436"/>
        <origin xyz="0.381678 0.001261 0.005168"/>
        <inertia ixx="0.00573099" ixy="-0.000131119" ixz="0.000380232" iyy="0.0118352" iyz="-2.26565e-05" izz="0.0114428"/>
      </inertial>
      <collision name="collision">
        <geometry>
          <mesh filename="package://abb_irb4600_gazebo/meshes/irb4600_60_205/collision/link_4.stl"/>
        </geometry>
      </collision>
      <visual name="visual">
        <geometry>
          <mesh filename="package://abb_irb4600_gazebo/meshes/irb4600_60_205/visual/link_4.stl"/>
        </geometry>
        <material name="yellow"/>
      </visual>
    </link>
    <link name="${prefix}link_5">
    <inertial>
        <mass value="0.62953"/>
        <origin xyz="0.011197 -0.001056 0.000109"/>
        <inertia ixx="0.000502815" ixy="-1.03173e-05" ixz="-8.74347e-08" iyy="0.00108856" iyz="2.07657e-07" izz="0.000918873"/>
      </inertial>
      <collision name="collision">
        <geometry>
          <mesh filename="package://abb_irb4600_gazebo/meshes/irb4600_60_205/collision/link_5.stl"/>
        </geometry>
      </collision>
      <visual name="visual">
        <geometry>
          <mesh filename="package://abb_irb4600_gazebo/meshes/irb4600_60_205/visual/link_5.stl"/>
        </geometry>
        <material name="yellow"/>
      </visual>
    </link>
    <link name="${prefix}link_6">
     <inertial>
        <mass value="0.137"/>
        <origin xyz="-0.00706 -0.00017 -1.32E-06" rpy="0 0 0"/>
        <inertia ixx="0.001" ixy="0" ixz="0" iyy="0.001" iyz="0" izz="0.001"/>
      </inertial>
      <collision name="collision">
        <geometry>
          <mesh filename="package://abb_irb4600_gazebo/meshes/irb4600_60_205/collision/link_6.stl"/>
        </geometry>
      </collision>
      <visual name="visual">
        <geometry>
          <mesh filename="package://abb_irb4600_gazebo/meshes/irb4600_60_205/visual/link_6.stl"/>
        </geometry>
        <material name="yellow"/>
      </visual>
    </link>
    <link name="${prefix}tool0"/>
    <!-- end of link list -->

    <!-- joint list -->
    <joint type="revolute" name="${prefix}joint_1">
      <origin xyz="0 0 0.495" rpy="0 0 0"/>
      <axis xyz="0 0 1"/>
      <parent link="${prefix}base_link"/>
      <child link="${prefix}link_1"/>
      <limit effort="0" lower="-3.141" upper="3.141" velocity="3.054"/>
    </joint>
    <joint type="revolute" name="${prefix}joint_2">
      <origin xyz="0.175 0 0" rpy="0 0 0"/>
      <axis xyz="0 1 0"/>
      <parent link="${prefix}link_1"/>
      <child link="${prefix}link_2"/>
      <limit effort="0" lower="-1.570" upper="2.617" velocity="3.054"/>
    </joint>
    <joint type="revolute" name="${prefix}joint_3">
      <origin xyz="0 0 0.9" rpy="0 0 0"/>
      <axis xyz="0 1 0"/>
      <parent link="${prefix}link_2"/>
      <child link="${prefix}link_3"/>
      <limit effort="0" lower="-3.141" upper="1.308" velocity="3.054"/>
    </joint>
    <joint type="revolute" name="${prefix}joint_4">
      <origin xyz="0 0 0.175" rpy="0 0 0"/>
      <axis xyz="1 0 0"/>
      <parent link="${prefix}link_3"/>
      <child link="${prefix}link_4"/>
      <limit effort="0" lower="-6.981" upper="6.981" velocity="4.363"/>
    </joint>
    <joint type="revolute" name="${prefix}joint_5">
      <origin xyz="0.960 0 0 " rpy="0 0 0"/>
      <axis xyz="0 1 0"/>
      <parent link="${prefix}link_4"/>
      <child link="${prefix}link_5"/>
      <limit effort="0" lower="-2.181" upper="2.094" velocity="4.363"/>
    </joint>
    <joint type="revolute" name="${prefix}joint_6">
      <origin xyz="0.135 0 0 " rpy="0 0 0"/>
      <axis xyz="1 0 0"/>
      <parent link="${prefix}link_5"/>
      <child link="${prefix}link_6"/>
      <limit effort="0" lower="-6.981" upper="6.981" velocity="6.283"/>
    </joint>
    <joint type="fixed" name="${prefix}joint_6-tool0">
      <parent link="${prefix}link_6"/>
      <child link="${prefix}tool0"/>
      <origin xyz="0 0 0" rpy="0 1.57079632679 0"/>
    </joint>
    <!-- end of joint list -->

    <!-- ROS base_link to ABB World Coordinates transform -->
    <link name="${prefix}base" />
    <joint name="${prefix}base_link-base" type="fixed">
      <origin xyz="0 0 0" rpy="0 0 0"/>
      <parent link="${prefix}base_link"/>
      <child link="${prefix}base"/>
    </joint>
  </xacro:macro>
</robot>
